<?xml version="1.0" encoding="UTF-8"?>
<testng-results ignored="0" total="5" passed="0" failed="5" skipped="0">
  <reporter-output>
    <line>
      <![CDATA[the method testCase2 got failed and screenshot is taken]]>
    </line>
    <line>
      <![CDATA[the method testCase3 got failed and screenshot is taken]]>
    </line>
    <line>
      <![CDATA[the method testCase4 got failed and screenshot is taken]]>
    </line>
    <line>
      <![CDATA[the method testCase5 got failed and screenshot is taken]]>
    </line>
    <line>
      <![CDATA[the method validLogin got failed and screenshot is taken]]>
    </line>
  </reporter-output>
  <suite started-at="2022-06-13T14:07:26 IST" name="Default suite" finished-at="2022-06-13T14:07:56 IST" duration-ms="30452">
    <groups>
    </groups>
    <test started-at="2022-06-13T14:07:26 IST" name="Default test" finished-at="2022-06-13T14:07:56 IST" duration-ms="30452">
      <class name="takesScreenshotDynamically.TestCase">
        <test-method is-config="true" signature="setUp()[pri:0, instance:takesScreenshotDynamically.TestCase@41e1e210]" started-at="2022-06-13T14:07:26 IST" name="setUp" finished-at="2022-06-13T14:07:37 IST" duration-ms="11902" status="PASS">
          <reporter-output>
          </reporter-output>
        </test-method> <!-- setUp -->
        <test-method signature="testCase2()[pri:0, instance:takesScreenshotDynamically.TestCase@41e1e210]" started-at="2022-06-13T14:07:37 IST" name="testCase2" finished-at="2022-06-13T14:07:38 IST" duration-ms="21" status="FAIL">
          <exception class="java.lang.AssertionError">
            <message>
              <![CDATA[null]]>
            </message>
            <full-stacktrace>
              <![CDATA[java.lang.AssertionError: null
at org.testng.Assert.fail(Assert.java:99)
at org.testng.Assert.fail(Assert.java:106)
at takesScreenshotDynamically.TestCase.testCase2(TestCase.java:42)
at java.base/jdk.internal.reflect.NativeMethodAccessorImpl.invoke0(Native Method)
at java.base/jdk.internal.reflect.NativeMethodAccessorImpl.invoke(NativeMethodAccessorImpl.java:77)
at java.base/jdk.internal.reflect.DelegatingMethodAccessorImpl.invoke(DelegatingMethodAccessorImpl.java:43)
at java.base/java.lang.reflect.Method.invoke(Method.java:568)
at org.testng.internal.MethodInvocationHelper.invokeMethod(MethodInvocationHelper.java:133)
at org.testng.internal.TestInvoker.invokeMethod(TestInvoker.java:598)
at org.testng.internal.TestInvoker.invokeTestMethod(TestInvoker.java:173)
at org.testng.internal.MethodRunner.runInSequence(MethodRunner.java:46)
at org.testng.internal.TestInvoker$MethodInvocationAgent.invoke(TestInvoker.java:824)
at org.testng.internal.TestInvoker.invokeTestMethods(TestInvoker.java:146)
at org.testng.internal.TestMethodWorker.invokeTestMethods(TestMethodWorker.java:146)
at org.testng.internal.TestMethodWorker.run(TestMethodWorker.java:128)
at java.base/java.util.ArrayList.forEach(ArrayList.java:1511)
at org.testng.TestRunner.privateRun(TestRunner.java:794)
at org.testng.TestRunner.run(TestRunner.java:596)
at org.testng.SuiteRunner.runTest(SuiteRunner.java:377)
at org.testng.SuiteRunner.runSequentially(SuiteRunner.java:371)
at org.testng.SuiteRunner.privateRun(SuiteRunner.java:332)
at org.testng.SuiteRunner.run(SuiteRunner.java:276)
at org.testng.SuiteRunnerWorker.runSuite(SuiteRunnerWorker.java:53)
at org.testng.SuiteRunnerWorker.run(SuiteRunnerWorker.java:96)
at org.testng.TestNG.runSuitesSequentially(TestNG.java:1212)
at org.testng.TestNG.runSuitesLocally(TestNG.java:1134)
at org.testng.TestNG.runSuites(TestNG.java:1063)
at org.testng.TestNG.run(TestNG.java:1031)
at org.testng.remote.AbstractRemoteTestNG.run(AbstractRemoteTestNG.java:115)
at org.testng.remote.RemoteTestNG.initAndRun(RemoteTestNG.java:251)
at org.testng.remote.RemoteTestNG.main(RemoteTestNG.java:77)
]]>
            </full-stacktrace>
          </exception> <!-- java.lang.AssertionError -->
          <reporter-output>
            <line>
              <![CDATA[the method testCase2 got failed and screenshot is taken]]>
            </line>
          </reporter-output>
        </test-method> <!-- testCase2 -->
        <test-method is-config="true" signature="tearDown()[pri:0, instance:takesScreenshotDynamically.TestCase@41e1e210]" started-at="2022-06-13T14:07:38 IST" name="tearDown" finished-at="2022-06-13T14:07:38 IST" duration-ms="279" status="PASS">
          <reporter-output>
          </reporter-output>
        </test-method> <!-- tearDown -->
        <test-method is-config="true" signature="setUp()[pri:0, instance:takesScreenshotDynamically.TestCase@41e1e210]" started-at="2022-06-13T14:07:38 IST" name="setUp" finished-at="2022-06-13T14:07:43 IST" duration-ms="4892" status="PASS">
          <reporter-output>
          </reporter-output>
        </test-method> <!-- setUp -->
        <test-method signature="testCase3()[pri:0, instance:takesScreenshotDynamically.TestCase@41e1e210]" started-at="2022-06-13T14:07:43 IST" name="testCase3" finished-at="2022-06-13T14:07:43 IST" duration-ms="2" status="FAIL">
          <exception class="java.lang.AssertionError">
            <message>
              <![CDATA[null]]>
            </message>
            <full-stacktrace>
              <![CDATA[java.lang.AssertionError: null
at org.testng.Assert.fail(Assert.java:99)
at org.testng.Assert.fail(Assert.java:106)
at takesScreenshotDynamically.TestCase.testCase3(TestCase.java:48)
at java.base/jdk.internal.reflect.NativeMethodAccessorImpl.invoke0(Native Method)
at java.base/jdk.internal.reflect.NativeMethodAccessorImpl.invoke(NativeMethodAccessorImpl.java:77)
at java.base/jdk.internal.reflect.DelegatingMethodAccessorImpl.invoke(DelegatingMethodAccessorImpl.java:43)
at java.base/java.lang.reflect.Method.invoke(Method.java:568)
at org.testng.internal.MethodInvocationHelper.invokeMethod(MethodInvocationHelper.java:133)
at org.testng.internal.TestInvoker.invokeMethod(TestInvoker.java:598)
at org.testng.internal.TestInvoker.invokeTestMethod(TestInvoker.java:173)
at org.testng.internal.MethodRunner.runInSequence(MethodRunner.java:46)
at org.testng.internal.TestInvoker$MethodInvocationAgent.invoke(TestInvoker.java:824)
at org.testng.internal.TestInvoker.invokeTestMethods(TestInvoker.java:146)
at org.testng.internal.TestMethodWorker.invokeTestMethods(TestMethodWorker.java:146)
at org.testng.internal.TestMethodWorker.run(TestMethodWorker.java:128)
at java.base/java.util.ArrayList.forEach(ArrayList.java:1511)
at org.testng.TestRunner.privateRun(TestRunner.java:794)
at org.testng.TestRunner.run(TestRunner.java:596)
at org.testng.SuiteRunner.runTest(SuiteRunner.java:377)
at org.testng.SuiteRunner.runSequentially(SuiteRunner.java:371)
at org.testng.SuiteRunner.privateRun(SuiteRunner.java:332)
at org.testng.SuiteRunner.run(SuiteRunner.java:276)
at org.testng.SuiteRunnerWorker.runSuite(SuiteRunnerWorker.java:53)
at org.testng.SuiteRunnerWorker.run(SuiteRunnerWorker.java:96)
at org.testng.TestNG.runSuitesSequentially(TestNG.java:1212)
at org.testng.TestNG.runSuitesLocally(TestNG.java:1134)
at org.testng.TestNG.runSuites(TestNG.java:1063)
at org.testng.TestNG.run(TestNG.java:1031)
at org.testng.remote.AbstractRemoteTestNG.run(AbstractRemoteTestNG.java:115)
at org.testng.remote.RemoteTestNG.initAndRun(RemoteTestNG.java:251)
at org.testng.remote.RemoteTestNG.main(RemoteTestNG.java:77)
]]>
            </full-stacktrace>
          </exception> <!-- java.lang.AssertionError -->
          <reporter-output>
            <line>
              <![CDATA[the method testCase3 got failed and screenshot is taken]]>
            </line>
          </reporter-output>
        </test-method> <!-- testCase3 -->
        <test-method is-config="true" signature="tearDown()[pri:0, instance:takesScreenshotDynamically.TestCase@41e1e210]" started-at="2022-06-13T14:07:43 IST" name="tearDown" finished-at="2022-06-13T14:07:43 IST" duration-ms="207" status="PASS">
          <reporter-output>
          </reporter-output>
        </test-method> <!-- tearDown -->
        <test-method is-config="true" signature="setUp()[pri:0, instance:takesScreenshotDynamically.TestCase@41e1e210]" started-at="2022-06-13T14:07:43 IST" name="setUp" finished-at="2022-06-13T14:07:46 IST" duration-ms="3073" status="PASS">
          <reporter-output>
          </reporter-output>
        </test-method> <!-- setUp -->
        <test-method signature="testCase4()[pri:0, instance:takesScreenshotDynamically.TestCase@41e1e210]" started-at="2022-06-13T14:07:46 IST" name="testCase4" finished-at="2022-06-13T14:07:46 IST" duration-ms="5" status="FAIL">
          <exception class="java.lang.AssertionError">
            <message>
              <![CDATA[null]]>
            </message>
            <full-stacktrace>
              <![CDATA[java.lang.AssertionError: null
at org.testng.Assert.fail(Assert.java:99)
at org.testng.Assert.fail(Assert.java:106)
at takesScreenshotDynamically.TestCase.testCase4(TestCase.java:54)
at java.base/jdk.internal.reflect.NativeMethodAccessorImpl.invoke0(Native Method)
at java.base/jdk.internal.reflect.NativeMethodAccessorImpl.invoke(NativeMethodAccessorImpl.java:77)
at java.base/jdk.internal.reflect.DelegatingMethodAccessorImpl.invoke(DelegatingMethodAccessorImpl.java:43)
at java.base/java.lang.reflect.Method.invoke(Method.java:568)
at org.testng.internal.MethodInvocationHelper.invokeMethod(MethodInvocationHelper.java:133)
at org.testng.internal.TestInvoker.invokeMethod(TestInvoker.java:598)
at org.testng.internal.TestInvoker.invokeTestMethod(TestInvoker.java:173)
at org.testng.internal.MethodRunner.runInSequence(MethodRunner.java:46)
at org.testng.internal.TestInvoker$MethodInvocationAgent.invoke(TestInvoker.java:824)
at org.testng.internal.TestInvoker.invokeTestMethods(TestInvoker.java:146)
at org.testng.internal.TestMethodWorker.invokeTestMethods(TestMethodWorker.java:146)
at org.testng.internal.TestMethodWorker.run(TestMethodWorker.java:128)
at java.base/java.util.ArrayList.forEach(ArrayList.java:1511)
at org.testng.TestRunner.privateRun(TestRunner.java:794)
at org.testng.TestRunner.run(TestRunner.java:596)
at org.testng.SuiteRunner.runTest(SuiteRunner.java:377)
at org.testng.SuiteRunner.runSequentially(SuiteRunner.java:371)
at org.testng.SuiteRunner.privateRun(SuiteRunner.java:332)
at org.testng.SuiteRunner.run(SuiteRunner.java:276)
at org.testng.SuiteRunnerWorker.runSuite(SuiteRunnerWorker.java:53)
at org.testng.SuiteRunnerWorker.run(SuiteRunnerWorker.java:96)
at org.testng.TestNG.runSuitesSequentially(TestNG.java:1212)
at org.testng.TestNG.runSuitesLocally(TestNG.java:1134)
at org.testng.TestNG.runSuites(TestNG.java:1063)
at org.testng.TestNG.run(TestNG.java:1031)
at org.testng.remote.AbstractRemoteTestNG.run(AbstractRemoteTestNG.java:115)
at org.testng.remote.RemoteTestNG.initAndRun(RemoteTestNG.java:251)
at org.testng.remote.RemoteTestNG.main(RemoteTestNG.java:77)
]]>
            </full-stacktrace>
          </exception> <!-- java.lang.AssertionError -->
          <reporter-output>
            <line>
              <![CDATA[the method testCase4 got failed and screenshot is taken]]>
            </line>
          </reporter-output>
        </test-method> <!-- testCase4 -->
        <test-method is-config="true" signature="tearDown()[pri:0, instance:takesScreenshotDynamically.TestCase@41e1e210]" started-at="2022-06-13T14:07:46 IST" name="tearDown" finished-at="2022-06-13T14:07:47 IST" duration-ms="212" status="PASS">
          <reporter-output>
          </reporter-output>
        </test-method> <!-- tearDown -->
        <test-method is-config="true" signature="setUp()[pri:0, instance:takesScreenshotDynamically.TestCase@41e1e210]" started-at="2022-06-13T14:07:47 IST" name="setUp" finished-at="2022-06-13T14:07:52 IST" duration-ms="5062" status="PASS">
          <reporter-output>
          </reporter-output>
        </test-method> <!-- setUp -->
        <test-method signature="testCase5()[pri:0, instance:takesScreenshotDynamically.TestCase@41e1e210]" started-at="2022-06-13T14:07:52 IST" name="testCase5" finished-at="2022-06-13T14:07:52 IST" duration-ms="1" status="FAIL">
          <exception class="java.lang.AssertionError">
            <message>
              <![CDATA[null]]>
            </message>
            <full-stacktrace>
              <![CDATA[java.lang.AssertionError: null
at org.testng.Assert.fail(Assert.java:99)
at org.testng.Assert.fail(Assert.java:106)
at takesScreenshotDynamically.TestCase.testCase5(TestCase.java:61)
at java.base/jdk.internal.reflect.NativeMethodAccessorImpl.invoke0(Native Method)
at java.base/jdk.internal.reflect.NativeMethodAccessorImpl.invoke(NativeMethodAccessorImpl.java:77)
at java.base/jdk.internal.reflect.DelegatingMethodAccessorImpl.invoke(DelegatingMethodAccessorImpl.java:43)
at java.base/java.lang.reflect.Method.invoke(Method.java:568)
at org.testng.internal.MethodInvocationHelper.invokeMethod(MethodInvocationHelper.java:133)
at org.testng.internal.TestInvoker.invokeMethod(TestInvoker.java:598)
at org.testng.internal.TestInvoker.invokeTestMethod(TestInvoker.java:173)
at org.testng.internal.MethodRunner.runInSequence(MethodRunner.java:46)
at org.testng.internal.TestInvoker$MethodInvocationAgent.invoke(TestInvoker.java:824)
at org.testng.internal.TestInvoker.invokeTestMethods(TestInvoker.java:146)
at org.testng.internal.TestMethodWorker.invokeTestMethods(TestMethodWorker.java:146)
at org.testng.internal.TestMethodWorker.run(TestMethodWorker.java:128)
at java.base/java.util.ArrayList.forEach(ArrayList.java:1511)
at org.testng.TestRunner.privateRun(TestRunner.java:794)
at org.testng.TestRunner.run(TestRunner.java:596)
at org.testng.SuiteRunner.runTest(SuiteRunner.java:377)
at org.testng.SuiteRunner.runSequentially(SuiteRunner.java:371)
at org.testng.SuiteRunner.privateRun(SuiteRunner.java:332)
at org.testng.SuiteRunner.run(SuiteRunner.java:276)
at org.testng.SuiteRunnerWorker.runSuite(SuiteRunnerWorker.java:53)
at org.testng.SuiteRunnerWorker.run(SuiteRunnerWorker.java:96)
at org.testng.TestNG.runSuitesSequentially(TestNG.java:1212)
at org.testng.TestNG.runSuitesLocally(TestNG.java:1134)
at org.testng.TestNG.runSuites(TestNG.java:1063)
at org.testng.TestNG.run(TestNG.java:1031)
at org.testng.remote.AbstractRemoteTestNG.run(AbstractRemoteTestNG.java:115)
at org.testng.remote.RemoteTestNG.initAndRun(RemoteTestNG.java:251)
at org.testng.remote.RemoteTestNG.main(RemoteTestNG.java:77)
]]>
            </full-stacktrace>
          </exception> <!-- java.lang.AssertionError -->
          <reporter-output>
            <line>
              <![CDATA[the method testCase5 got failed and screenshot is taken]]>
            </line>
          </reporter-output>
        </test-method> <!-- testCase5 -->
        <test-method is-config="true" signature="tearDown()[pri:0, instance:takesScreenshotDynamically.TestCase@41e1e210]" started-at="2022-06-13T14:07:52 IST" name="tearDown" finished-at="2022-06-13T14:07:52 IST" duration-ms="342" status="PASS">
          <reporter-output>
          </reporter-output>
        </test-method> <!-- tearDown -->
        <test-method is-config="true" signature="setUp()[pri:0, instance:takesScreenshotDynamically.TestCase@41e1e210]" started-at="2022-06-13T14:07:52 IST" name="setUp" finished-at="2022-06-13T14:07:56 IST" duration-ms="3663" status="PASS">
          <reporter-output>
          </reporter-output>
        </test-method> <!-- setUp -->
        <test-method signature="validLogin()[pri:0, instance:takesScreenshotDynamically.TestCase@41e1e210]" started-at="2022-06-13T14:07:56 IST" name="validLogin" finished-at="2022-06-13T14:07:56 IST" duration-ms="73" status="FAIL">
          <exception class="org.openqa.selenium.NoSuchWindowException">
            <message>
              <![CDATA[no such window: target window already closed
from unknown error: web view not found
  (Session info: chrome=102.0.5005.115)
Build info: version: '4.1.3', revision: '7b1ebf28ef'
System info: host: 'DESKTOP-F56SB7Q', ip: '192.168.43.247', os.name: 'Windows 10', os.arch: 'amd64', os.version: '10.0', java.version: '17.0.1'
Driver info: org.openqa.selenium.chrome.ChromeDriver
Command: [f4307b32e4d8dee19705972b90cbdf2f, getTitle {}]
Capabilities {acceptInsecureCerts: false, browserName: chrome, browserVersion: 102.0.5005.115, chrome: {chromedriverVersion: 102.0.5005.61 (0e59bcc00cc4..., userDataDir: C:\Users\PRATHM~1\AppData\L...}, goog:chromeOptions: {debuggerAddress: localhost:62999}, javascriptEnabled: true, networkConnectionEnabled: false, pageLoadStrategy: normal, platform: WINDOWS, platformName: WINDOWS, proxy: Proxy(), se:cdp: ws://localhost:62999/devtoo..., se:cdpVersion: 102.0.5005.115, setWindowRect: true, strictFileInteractability: false, timeouts: {implicit: 0, pageLoad: 300000, script: 30000}, unhandledPromptBehavior: dismiss and notify, webauthn:extension:credBlob: true, webauthn:extension:largeBlob: true, webauthn:virtualAuthenticators: true}
Session ID: f4307b32e4d8dee19705972b90cbdf2f]]>
            </message>
            <full-stacktrace>
              <![CDATA[org.openqa.selenium.NoSuchWindowException: no such window: target window already closed
from unknown error: web view not found
  (Session info: chrome=102.0.5005.115)
Build info: version: '4.1.3', revision: '7b1ebf28ef'
System info: host: 'DESKTOP-F56SB7Q', ip: '192.168.43.247', os.name: 'Windows 10', os.arch: 'amd64', os.version: '10.0', java.version: '17.0.1'
Driver info: org.openqa.selenium.chrome.ChromeDriver
Command: [f4307b32e4d8dee19705972b90cbdf2f, getTitle {}]
Capabilities {acceptInsecureCerts: false, browserName: chrome, browserVersion: 102.0.5005.115, chrome: {chromedriverVersion: 102.0.5005.61 (0e59bcc00cc4..., userDataDir: C:\Users\PRATHM~1\AppData\L...}, goog:chromeOptions: {debuggerAddress: localhost:62999}, javascriptEnabled: true, networkConnectionEnabled: false, pageLoadStrategy: normal, platform: WINDOWS, platformName: WINDOWS, proxy: Proxy(), se:cdp: ws://localhost:62999/devtoo..., se:cdpVersion: 102.0.5005.115, setWindowRect: true, strictFileInteractability: false, timeouts: {implicit: 0, pageLoad: 300000, script: 30000}, unhandledPromptBehavior: dismiss and notify, webauthn:extension:credBlob: true, webauthn:extension:largeBlob: true, webauthn:virtualAuthenticators: true}
Session ID: f4307b32e4d8dee19705972b90cbdf2f
at java.base/jdk.internal.reflect.NativeConstructorAccessorImpl.newInstance0(Native Method)
at java.base/jdk.internal.reflect.NativeConstructorAccessorImpl.newInstance(NativeConstructorAccessorImpl.java:77)
at java.base/jdk.internal.reflect.DelegatingConstructorAccessorImpl.newInstance(DelegatingConstructorAccessorImpl.java:45)
at java.base/java.lang.reflect.Constructor.newInstanceWithCaller(Constructor.java:499)
at java.base/java.lang.reflect.Constructor.newInstance(Constructor.java:480)
at org.openqa.selenium.remote.codec.w3c.W3CHttpResponseCodec.createException(W3CHttpResponseCodec.java:200)
at org.openqa.selenium.remote.codec.w3c.W3CHttpResponseCodec.decode(W3CHttpResponseCodec.java:133)
at org.openqa.selenium.remote.codec.w3c.W3CHttpResponseCodec.decode(W3CHttpResponseCodec.java:53)
at org.openqa.selenium.remote.HttpCommandExecutor.execute(HttpCommandExecutor.java:184)
at org.openqa.selenium.remote.service.DriverCommandExecutor.invokeExecute(DriverCommandExecutor.java:167)
at org.openqa.selenium.remote.service.DriverCommandExecutor.execute(DriverCommandExecutor.java:142)
at org.openqa.selenium.remote.RemoteWebDriver.execute(RemoteWebDriver.java:567)
at org.openqa.selenium.remote.RemoteWebDriver.execute(RemoteWebDriver.java:622)
at org.openqa.selenium.remote.RemoteWebDriver.execute(RemoteWebDriver.java:626)
at org.openqa.selenium.remote.RemoteWebDriver.getTitle(RemoteWebDriver.java:335)
at takesScreenshotDynamically.TestCase.validLogin(TestCase.java:26)
at java.base/jdk.internal.reflect.NativeMethodAccessorImpl.invoke0(Native Method)
at java.base/jdk.internal.reflect.NativeMethodAccessorImpl.invoke(NativeMethodAccessorImpl.java:77)
at java.base/jdk.internal.reflect.DelegatingMethodAccessorImpl.invoke(DelegatingMethodAccessorImpl.java:43)
at java.base/java.lang.reflect.Method.invoke(Method.java:568)
at org.testng.internal.MethodInvocationHelper.invokeMethod(MethodInvocationHelper.java:133)
at org.testng.internal.TestInvoker.invokeMethod(TestInvoker.java:598)
at org.testng.internal.TestInvoker.invokeTestMethod(TestInvoker.java:173)
at org.testng.internal.MethodRunner.runInSequence(MethodRunner.java:46)
at org.testng.internal.TestInvoker$MethodInvocationAgent.invoke(TestInvoker.java:824)
at org.testng.internal.TestInvoker.invokeTestMethods(TestInvoker.java:146)
at org.testng.internal.TestMethodWorker.invokeTestMethods(TestMethodWorker.java:146)
at org.testng.internal.TestMethodWorker.run(TestMethodWorker.java:128)
at java.base/java.util.ArrayList.forEach(ArrayList.java:1511)
at org.testng.TestRunner.privateRun(TestRunner.java:794)
at org.testng.TestRunner.run(TestRunner.java:596)
at org.testng.SuiteRunner.runTest(SuiteRunner.java:377)
at org.testng.SuiteRunner.runSequentially(SuiteRunner.java:371)
at org.testng.SuiteRunner.privateRun(SuiteRunner.java:332)
at org.testng.SuiteRunner.run(SuiteRunner.java:276)
at org.testng.SuiteRunnerWorker.runSuite(SuiteRunnerWorker.java:53)
at org.testng.SuiteRunnerWorker.run(SuiteRunnerWorker.java:96)
at org.testng.TestNG.runSuitesSequentially(TestNG.java:1212)
at org.testng.TestNG.runSuitesLocally(TestNG.java:1134)
at org.testng.TestNG.runSuites(TestNG.java:1063)
at org.testng.TestNG.run(TestNG.java:1031)
at org.testng.remote.AbstractRemoteTestNG.run(AbstractRemoteTestNG.java:115)
at org.testng.remote.RemoteTestNG.initAndRun(RemoteTestNG.java:251)
at org.testng.remote.RemoteTestNG.main(RemoteTestNG.java:77)
]]>
            </full-stacktrace>
          </exception> <!-- org.openqa.selenium.NoSuchWindowException -->
          <reporter-output>
            <line>
              <![CDATA[the method validLogin got failed and screenshot is taken]]>
            </line>
          </reporter-output>
        </test-method> <!-- validLogin -->
        <test-method is-config="true" signature="tearDown()[pri:0, instance:takesScreenshotDynamically.TestCase@41e1e210]" started-at="2022-06-13T14:07:56 IST" name="tearDown" finished-at="2022-06-13T14:07:56 IST" duration-ms="198" status="PASS">
          <reporter-output>
          </reporter-output>
        </test-method> <!-- tearDown -->
      </class> <!-- takesScreenshotDynamically.TestCase -->
    </test> <!-- Default test -->
  </suite> <!-- Default suite -->
</testng-results>
